Workbook
Name DocumentTitle: 'Cover Page'!$A$25
Name Print_Area_MI: #REF!
Name Print_Area_MI: #REF!
Name Print_Area_MI: #REF!
Name PROJDETAILS_PROJNO: LEFT('[1]Cover page'!$A$29,5)
Name ProjectTitle: 'Cover Page'!$A$27
Name PRUEBA: #N/A

Sheet Cover Page
A25: PROCESS CONTROL TABLES - FLOTATION (F16, F17, F18)
A27: KCGM GROWTH PROJECT
A29: 2000-F16-LST-PR-10001
A32: NORTHERN STAR RESOURCES LIMITED
A41: PRIMERO PROJECT NUMBER: 23517
A43: DATE | B43: REVISION | C43: STATUS | D43: PREPARED | E43: REVIEWED | F43: APPROVED
A44: 45492 | B44: 0 | C44: Issued for Design | D44: J. Jones | E44: E. Wilmot | F44: D. Moltoni
A45: 45532 | B45: 1 | C45: Reissued for Design | D45: J. Ho | E45: J. Jones | F45: D. Moltoni
A46: 45602 | B46: 2 | C46: Reissued for Design | D46: J. De Man | E46: F. Chua | F46: L. Stacey

Sheet Revisions
A1: PROCESS CONTROL TABLES
A2: REVISION HISTORY
A3: KCGM GROWTH PROJECT
A4: ='Cover Page'!A29 -> 2000-F16-LST-PR-10001
A5: ='Cover Page'!A32 -> NORTHERN STAR RESOURCES LIMITED
A7: Revision | C7: Document Changes | F7: Date
A8: A for Sequence Flowchart Review Only | C8: - Yellow highlight indicates TBC | F8: 45274
C9: - Does not include the remainder of the Process Control Tables
A11: B for Internal Review | C11: - Yellow highlight indicates TBC | F11: 45398
A14: C for Client Review | C14: - Yellow highlight indicates TBC | F14: 45440
A17: 0 for Design | C17: - Yellow highlight indicates TBC | F17: ='Cover Page'!A44 -> 45492
A20: 1 for Design | C20: - Yellow highlight indicates TBC | F20: 45532
C21: - Revision 2 changes highlighted in light orange
C22: - Revision aligns with Rev 0 P&IDs for Areas F16,17,18
A23: 2 for Design | C23: - Yellow highlight indicates TBC | F23: 45602
C24: - Revision 2 changes highlighted in light orange

Sheet TOC
A1: =ProjectTitle -> KCGM GROWTH PROJECT
A2: ='Cover Page'!DocumentTitle -> PROCESS CONTROL TABLES - FLOTATION (F16, F17, F18)
A3: ='Cover Page'!A29 -> 2000-F16-LST-PR-10001
B5: Table of Contents | F5: Total | G5: Complete (%) | K5: Alarms | L5: Priority | M5: Count | N5: % | S5: Abbreviations
B6: 1 | C6: Analogue Inputs | F6: ='1. Analogue Input'!E460 -> 451 | G6: 90 | K6: 1 | L6: Urgent (Critical Failure) | M6: =COUNTIF('13. Alarm Database'!L7:L653,"Urgent") -> 20 | N6: 100 | S6: FC | T6: Fail closed
B7: 2 | C7: Analogue Outputs | F7: ='2. Analogue Output'!E11 -> 2 | G7: 100 | K7: 2 | L7: High (Fault/Error) | M7: =COUNTIF('13. Alarm Database'!L7:L653,"High") -> 210 | N7: 100 | S7: FO | T7: Fail open
B8: 3 | C8: Digital Inputs | F8: ='3. Digital Input'!E489 -> 479 | G8: 100 | K8: 3 | L8: Low (Warning) | M8: =COUNTIF('13. Alarm Database'!L7:L653,"Low") -> 276 | N8: 100 | S8: FL | T8: Fail last
B9: 4 | C9: Digital Outputs | F9: ='4. Digital Output'!E28 -> 17 | G9: 100 | K9: 4 | L9: Information/Event (Logging) | M9: =COUNTIF('13. Alarm Database'!L7:L653,"Logging")+COUNTIF('13. Alarm Database'!L7:L653,"Logging \ Review the alarm for urgency (Incorrect Alarm Ranking)")+COUNTIF('13. Alarm Database'!L7:L653,"Low \ Review the alarm for urgency")+COUNTIF('13. Alarm Database'!L7:L653,"High \ Review the alarm for urgency")+COUNTIF('13. Alarm Database'!L7:L653,"Logging \ Review the alarm priority (Invalid Alarm Ranking)") -> 141 | N9: 100 | S9: LCP | T9: Local control panel
B10: 5 | C10: Totalisers | F10: ='5. Totalisers'!E15 -> 4 | G10: 100 | L10: Total | M10: =SUM(M6:M9) -> 647 | N10: 100 | S10: LCS | T10: Local control station
B11: 6 | C11: On/Off Valves | F11: ='6. OnOff Valves'!E183 -> 83 | G11: 100 | S11: A_Lo | T11: Low alarm
B12: 7 | C12: Control Valves | F12: ='7. Control Valves'!E54 -> 37 | G12: 100 | S12: A_Hi | T12: High alarm
B13: 8 | C13: PID Controllers | F13: ='8. PID Cont'!E62 -> 45 | G13: 100 | S13: A_LL | T13: Low-Low alarm
B14: 9 | C14: Drives & Interlocks | F14: ='9. Drives'!A889 -> 69 | G14: 98 | S14: A_HH | T14: High-High alarm
B15: 10 | C15: Sequences | F15: ='10. Sequence'!A13 -> 0 | G15: 100 | S15: P_Lo | T15: Low process switchpoint
B16: 11 | C16: Calculations | F16: ='11. Calculation'!A65 -> 15 | G16: 100 | S16: P_Hi | T16: High process switchpoint
B17: 12 | C17: Misc. | F17: ='12. Misc'!A47 -> 39 | G17: 100 | S17: P_LL | T17: Low-Low process switchpoint
E18: Total | F18: =SUM(F6:F17) -> 1241 | G18: 100 | S18: P_HH | T18: High-High process switchpoint
S19: OIT | T19: Operator interface terminal
S20: Range | T20: Instrument range
S21: SEQ | T21: Sequence
S22: TBA | T22: To be advised
S23: v | T23: Vendor controlled
S24: VTA | T24: Vendor to advise
S25: x | T25: PCS controlled

Sheet 1. Analogue Input
E1: KCGM GROWTH PROJECT
E2: PROCESS CONTROL TABLES - FLOTATION (F16, F17, F18)
E3: 2000-F16-LST-PR-10001
A4: ANALOGUE INSTRUMENTS (AI)
E5: Tag Source | F5: Tag Name | G5: P&ID | H5: Description | I5: Abbreviated Description (Faceplate) | K5: Range | N5: Process Switchpoints | Z5: Alarms | AH5: Alarm Priority
A6: Area | B6: Type | C6: Loop No. | D6: Suffix | J6: Trend (sec) | K6: Min | L6: Max | M6: Unit | N6: P_LL | O6: P_LL Delay ON (sec) | P6: P_LL Delay OFF (sec) | Q6: P_Lo | R6: P_Lo Delay ON (sec) | S6: P_Lo Delay OFF (sec) | T6: P_Hi | U6: P_Hi Delay ON (sec) | V6: P_Hi Delay OFF (sec) | W6: P_HH | X6: P_HH Delay ON (sec) | Y6: P_HH Delay OFF (sec) | Z6: A_LL | AA6: A_LL Delay (sec) | AB6: A_Lo | AC6: A_Lo Delay (sec) | AD6: A_Hi | AE6: A_Hi Delay (sec) | AF6: A_HH | AG6: A_HH Delay (sec) | AH6: A_LL | AI6: A_Lo | AJ6: A_Hi | AK6: A_HH | AL6: Alarm Masking Conditions | AM6: Comments | AN6: Rev
E7: FIT16001 | F7: FI16001 | G7: 2000-F16-PID-PR-10001 | H7: F16-CF-411 Rougher Flotation Cell 1 Process Water Flow Indicating Transmitter | I7: Flotation HP Prcss Water | J7: 1 | K7: 0 | L7: 700 | M7: m3/hr | AB7: 200 | AC7: 5 | AD7: 500 | AE7: 5 | AL7: DUTY F24PW417/418 NOT RUNNING | AM7: Alarm setpoints to be confirmed during commissioning. Alarm enabled delay of 20 seconds on HP Process Water Pump start-up (duration to be confirmed during commissioning). | AN7: C
E8: PIT16012 | F8: PI16012 | G8: 2000-F16-PID-PR-10001 | H8: F16-CF-411 Rougher Flotation Cell 1 Low Pressure Air Pressure Transmitter | I8: F16CF411 Blower Air | J8: 1 | K8: 0 | L8: 500 | M8: kPa(g) | AB8: 90 | AC8: 5 | AD8: 130 | AE8: 5 | AL8: Duty F16BW401 AND 402 AND 403 AND 404 NOT RUNNING | AM8: Nominal pressure: 104.5 kPa(g) Maximum pressure: 119.7 kPa(g) Alarm setpoints to be confirmed during commissioning. Alarm enabled delay of 10 seconds during blower start-up. | AN8: 0
E9: TT16014 | F9: TI16014 | G9: 2000-F16-PID-PR-10001 | H9: F16-CF-411 Rougher Flotation Cell 1 Gear Box Oil Temperature Transmitter | I9: F16CF411 G/Box Oil | J9: 1 | K9: -5 | L9: 300 | M9: °C | N9: 15 | O9: 5 | Q9: 23 | R9: 5 | T9: 55 | U9: 5 | W9: 65 | X9: 5 | AD9: 80 | AE9: 5 | AF9: 90 | AG9: 5 | AM9: Source: 2000-ME001.4-F16-50001 and 2000-ME001.4-M02-50001. Hysteresis of 5 degrees for Alarm High High. P_HH > F16-FN-497 turns on P_Hi < F16-FN-497 turns off P_Lo > F16-HT-562 and F16-HT-563 turns off P_LL < F16-HT-562 and F16-HT-563 turns on A_Hi > Alarm - inspection of gear unit required A_HH > F16-AG-421 trips | AN9: 1
E10: PT16015 | F10: PI16015 | G10: 2000-F16-PID-PR-10001 | H10: F16-CF-411 Rougher Flotation Cell 1 Gear Box Oil Pressure Transmitter | I10: F16CF411 G/Box Oil | J10: 1 | K10: 0 | L10: 1600 | M10: kPa(g) | Z10: 50 | AA10: 5 | AB10: 70 | AC10: 5 | AD10: 800 | AE10: 5 | AF10: 1000 | AG10: 5 | AM10: Source: 2000-ME001.4-M02-50001. A_HH > Unit shutdown. A_Hi > Alarm - inspection of gearbox required A_Lo < Alarm - inspection of gearbox required A_LL < Agitator Trip Alarm enabled delay of 10 seconds on start-up. | AN10: 0
E11: PDIT16018 | F11: PDI16018 | G11: 2000-F16-PID-PR-10001 | H11: F16-CF-411 Rougher Flotation Cell 1 Gear Box Filter Pressure Differential Transmitter | I11: F16CF411 G/Box Fltr Dlta | J11: 1 | K11: -100 | L11: 600 | M11: kPa(g) | AD11: 200 | AE11: 5 | AM11: Source: 2000-ME001.4-M02-50001. Alarm enabled delay of 10 seconds on agitator start-up. | AN11: 1
E12: VT16019 | F12: VI16019 | G12: 2000-F16-PID-PR-10001 | H12: F16-CF-411 Rougher Flotation Cell 1 Gear Box Vibration Transmitter | I12: F16CF411 G/Box | J12: 1 | K12: 0 | L12: 15 | M12: mm/s | AD12: 8 | AE12: 5 | AF12: 12 | AG12: 5 | AM12: Source: 2000-ME001.4-M02-50001. Alarm enabled delay of 10 seconds on agitator start-up. | AN12: 1
E13: VT16020 | F13: VI16020 | G13: 2000-F16-PID-PR-10001 | H13: F16-CF-411 Rougher Flotation Cell 1 Motor Vibration Transmitter | I13: F16CF411 Motor | J13: 1 | K13: 0 | L13: 15 | M13: mm/s | AD13: 4 | AE13: 5 | AF13: 7.1 | AG13: 5 | AM13: Source: 2000-ME001.4-M02-50001. Alarm enabled delay of 10 seconds on agitator start-up. | AN13: 1
E14: PIT16052 | F14: PI16052 | G14: 2000-F16-PID-PR-10002 | H14: F16-CF-412 Rougher Flotation Cell 2 Low Pressure Air Pressure Transmitter | I14: F16CF412 Blower Air | J14: 1 | K14: 0 | L14: 500 | M14: kPa(g) | AB14: 90 | AC14: 5 | AD14: 130 | AE14: 5 | AL14: Duty F16BW401 AND 402 AND 403 AND 404 NOT RUNNING | AM14: Nominal pressure: 104.5 kPa(g) Maximum pressure: 119.7 kPa(g) Alarm setpoints to be confirmed during commissioning. Alarm enabled delay of 10 seconds during blower start-up. | AN14: 0
E15: TT16054 | F15: TI16054 | G15: 2000-F16-PID-PR-10002 | H15: F16-CF-412 Rougher Flotation Cell 2 Gear Box Oil Temperature Transmitter | I15: F16CF412 G/Box Oil | J15: 1 | K15: -5 | L15: 300 | M15: °C | N15: 15 | O15: 5 | Q15: 23 | R15: 5 | T15: 55 | U15: 5 | W15: 65 | X15: 5 | AD15: 80 | AE15: 5 | AF15: 90 | AG15: 5 | AM15: Source: 2000-ME001.4-F16-50001 and 2000-ME001.4-M02-50001. Hysteresis of 5 degrees for Alarm High High. P_HH > F16-FN-498 turns on P_Hi < F16-FN-498 turns off P_Lo > F16-HT-564 and F16-HT-565 turns off P_LL < F16-HT-564 and F16-HT-565 turns on A_Hi > Alarm - inspection of gear unit required A_HH > F16-AG-422 trips | AN15: 1
E16: PT16055 | F16: PI16055 | G16: 2000-F16-PID-PR-10002 | H16: F16-CF-412 Rougher Flotation Cell 2 Gear Box Oil Pressure Transmitter | I16: F16CF412 G/Box Oil | J16: 1 | K16: 0 | L16: 1600 | M16: kPa | Z16: 50 | AA16: 5 | AB16: 70 | AC16: 5 | AD16: 800 | AE16: 5 | AF16: 1000 | AG16: 5 | AM16: Source: 2000-ME001.4-M02-50001. A_HH > Unit shutdown. A_Hi > Alarm - inspection of gearbox required A_Lo < Alarm - inspection of gearbox required A_LL < Agitator Trip Alarm enabled delay of 10 seconds on start-up. | AN16: B
E17: PDIT16058 | F17: PDI16058 | G17: 2000-F16-PID-PR-10002 | H17: F16-CF-412 Rougher Flotation Cell 2 Gear Box Filter Pressure Differential Transmitter | I17: F16CF412 G/Box Fltr Dlta | J17: 1 | K17: -100 | L17: 600 | M17: kPa(g) | AD17: 200 | AE17: 5 | AM17: Source: 2000-ME001.4-M02-50001. Alarm enabled delay of 10 seconds on agitator start-up. | AN17: 1
E18: VT16059 | F18: VI16059 | G18: 2000-F16-PID-PR-10002 | H18: F16-CF-412 Rougher Flotation Cell 2 Gear Box Vibration Transmitter | I18: F16CF412 G/Box | J18: 1 | K18: 0 | L18: 15 | M18: mm/s | AD18: 8 | AE18: 5 | AF18: 12 | AG18: 5 | AM18: Source: 2000-ME001.4-M02-50001. Alarm enabled delay of 10 seconds on agitator start-up. | AN18: 1
E19: VT16060 | F19: VI16060 | G19: 2000-F16-PID-PR-10002 | H19: F16-CF-412 Rougher Flotation Cell 2 Motor Vibration Transmitter | I19: F16CF412 Motor | J19: 1 | K19: 0 | L19: 15 | M19: mm/s | AD19: 4 | AE19: 5 | AF19: 7.1 | AG19: 5 | AM19: Source: 2000-ME001.4-M02-50001. Alarm enabled delay of 10 seconds on agitator start-up. | AN19: 1
E20: PIT16062 | F20: PI16062 | G20: 2000-F16-PID-PR-10002 | H20: F16-CF-413 Rougher Flotation Cell 3 Low Pressure Air Pressure Transmitter | I20: F16CF413 Blower Air | J20: 1 | K20: 0 | L20: 500 | M20: kPa(g) | AB20: 90 | AC20: 5 | AD20: 130 | AE20: 5 | AL20: Duty F16BW401 AND 402 AND 403 AND 404 NOT RUNNING | AM20: Nominal pressure: 104.5 kPa(g) Maximum pressure: 119.7 kPa(g) Alarm setpoints to be confirmed during commissioning. Alarm enabled delay of 10 seconds during blower start-up. | AN20: 0
E21: TT16064 | F21: TI16064 | G21: 2000-F16-PID-PR-10002 | H21: F16-CF-413 Rougher Flotation Cell 3 Gear Box Oil Temperature Transmitter | I21: F16CF413 G/Box Oil | J21: 1 | K21: -5 | L21: 300 | M21: °C | N21: 15 | O21: 5 | Q21: 23 | R21: 5 | T21: 55 | U21: 5 | W21: 65 | X21: 5 | AD21: 80 | AE21: 5 | AF21: 90 | AG21: 5 | AM21: Source: 2000-ME001.4-F16-50001 and 2000-ME001.4-M02-50001. Hysteresis of 5 degrees for Alarm High High. P_HH >= F16-FN-499 turns on P_Hi <= F16-FN-499 turns off P_Lo >= F16-HT-566 and F16-HT-567 turns off P_LL <= F16-HT-566 and F16-HT-567 turns on A_Hi >= Alarm - inspection of gear unit required A_HH >= F16-AG-423 trips | AN21: 1
E22: PT16065 | F22: PI16065 | G22: 2000-F16-PID-PR-10002 | H22: F16-CF-413 Rougher Flotation Cell 3 Gear Box Oil Pressure Transmitter | I22: F16CF413 G/Box Oil | J22: 1 | K22: 0 | L22: 1600 | M22: kPa | Z22: 50 | AA22: 5 | AB22: 70 | AC22: 5 | AD22: 800 | AE22: 5 | AF22: 1000 | AG22: 5 | AM22: Source: 2000-ME001.4-M02-50001. A_HH > Unit shutdown. A_Hi > Alarm - inspection of gearbox required A_Lo < Alarm - inspection of gearbox required A_LL < Agitator Trip Alarm enabled delay of 10 seconds on start-up. | AN22: B
E23: PDIT16068 | F23: PDI16068 | G23: 2000-F16-PID-PR-10002 | H23: F16-CF-413 Rougher Flotation Cell 3 Gear Box Filter Pressure Differential Transmitter | I23: F16CF413 G/Box Fltr Dlta | J23: 1 | K23: -100 | L23: 600 | M23: kPa(g) | AD23: 200 | AE23: 5 | AM23: Source: 2000-ME001.4-M02-50001. Alarm enabled delay of 10 seconds on agitator start-up. | AN23: 1
E24: VT16069 | F24: VI16069 | G24: 2000-F16-PID-PR-10002 | H24: F16-CF-413 Rougher Flotation Cell 3 Gear Box Vibration Transmitter | I24: F16CF413 G/Box | J24: 1 | K24: 0 | L24: 15 | M24: mm/s | AD24: 8 | AE24: 5 | AF24: 12 | AG24: 5 | AM24: Source: 2000-ME001.4-M02-50001. Alarm enabled delay of 10 seconds on agitator start-up. | AN24: 1
E25: VT16070 | F25: VI16070 | G25: 2000-F16-PID-PR-10002 | H25: F16-CF-413 Rougher Flotation Cell 3 Motor Vibration Transmitter | I25: F16CF413 Motor | J25: 1 | K25: 0 | L25: 15 | M25: mm/s | AD25: 4 | AE25: 5 | AF25: 7.1 | AG25: 5 | AM25: Source: 2000-ME001.4-M02-50001. Alarm enabled delay of 10 seconds on agitator start-up. | AN25: 1
E26: PIT16082 | F26: PI16082 | G26: 2000-F16-PID-PR-10003 | H26: F16-CF-414 Scavenger Flotation Cell 1 Low Pressure Air Pressure Indicating Transmitter | I26: F16CF414 Blower Air | J26: 1 | K26: 0 | L26: 500 | M26: kPa(g) | AB26: 90 | AC26: 5 | AD26: 130 | AE26: 5 | AL26: Duty F16BW401 AND 402 AND 403 AND 404 NOT RUNNING | AM26: Nominal pressure: 104.5 kPa(g) Maximum pressure: 119.7 kPa(g) Alarm setpoints to be confirmed during commissioning. Alarm enabled delay of 10 seconds during blower start-up. | AN26: 0
E27: TT16084 | F27: TI16084 | G27: 2000-F16-PID-PR-10003 | H27: F16-CF-414 Scavenger Flotation Cell 1 Gear Box Oil Temperature Transmitter | I27: F16CF414 G/Box Oil | J27: 1 | K27: -5 | L27: 300 | M27: °C | N27: 15 | O27: 5 | Q27: 23 | R27: 5 | T27: 55 | U27: 5 | W27: 65 | X27: 5 | AD27: 80 | AE27: 5 | AF27: 90 | AG27: 5 | AM27: Source: 2000-ME001.4-F16-50001 and 2000-ME001.4-M02-50001. Hysteresis of 5 degrees for Alarm High High. P_HH > F16-FN-500 turns on P_Hi < F16-FN-500 turns off P_Lo > F16-HT-568 and F16-HT-569 turns off P_LL < F16-HT-568 and F16-HT-569 turns on A_Hi > Alarm - inspection of gear unit required A_HH > F16-AG-424 trips | AN27: 1
E28: PT16085 | F28: PI16085 | G28: 2000-F16-PID-PR-10003 | H28: F16-CF-414 Scavenger Flotation Cell 1 Gear Box Oil Pressure Transmitter | I28: F16CF414 G/Box Oil | J28: 1 | K28: 0 | L28: 1600 | M28: kPa | Z28: 50 | AA28: 5 | AB28: 70 | AC28: 5 | AD28: 800 | AE28: 5 | AF28: 1000 | AG28: 5 | AM28: Source: 2000-ME001.4-M02-50001. A_HH > Unit shutdown. A_Hi > Alarm - inspection of gearbox required A_Lo < Alarm - inspection of gearbox required A_LL < Agitator Trip Alarm enabled delay of 10 seconds on start-up. | AN28: C
E29: PDIT16088 | F29: PDI16088 | G29: 2000-F16-PID-PR-10003 | H29: F16-CF-414 Scavenger Flotation Cell 1 Gear Box Filter Pressure Differential Transmitter | I29: F16CF414 G/Box Fltr Dlta | J29: 1 | K29: -100 | L29: 600 | M29: kPa(g) | AD29: 200 | AE29: 5 | AM29: Source: 2000-ME001.4-M02-50001. Alarm enabled delay of 10 seconds on agitator start-up. | AN29: 1
E30: VT16089 | F30: VI16089 | G30: 2000-F16-PID-PR-10003 | H30: F16-CF-414 Scavenger Flotation Cell 1 Gear Box Vibration Transmitter | I30: F16CF414 G/Box | J30: 1 | K30: 0 | L30: 15 | M30: mm/s | AD30: 8 | AE30: 5 | AF30: 12 | AG30: 5 | AM30: Source: 2000-ME001.4-M02-50001. Alarm enabled delay of 10 seconds on agitator start-up. | AN30: 1
E31: VT16090 | F31: VI16090 | G31: 2000-F16-PID-PR-10003 | H31: F16-CF-414 Scavenger Flotation Cell 1 Motor Vibration Transmitter | I31: F16CF414 Motor | J31: 1 | K31: 0 | L31: 15 | M31: mm/s | AD31: 4 | AE31: 5 | AF31: 7.1 | AG31: 5 | AM31: Source: 2000-ME001.4-M02-50001. Alarm enabled delay of 10 seconds on agitator start-up. | AN31: 1
E32: PIT16092 | F32: PI16092 | G32: 2000-F16-PID-PR-10003 | H32: F16-CF-415 Scavenger Flotation Cell 2 Low Pressure Air Pressure Indicating Transmitter | I32: F16CF415 Blower Air | J32: 1 | K32: 0 | L32: 500 | M32: kPa(g) | AB32: 90 | AC32: 5 | AD32: 130 | AE32: 5 | AL32: Duty F16BW401 AND 402 AND 403 AND 404 NOT RUNNING | AM32: Nominal pressure: 104.5 kPa(g) Maximum pressure: 119.7 kPa(g) Alarm setpoints to be confirmed during commissioning. Alarm enabled delay of 10 seconds during blower start-up. | AN32: 0
E33: TT16094 | F33: TI16094 | G33: 2000-F16-PID-PR-10003 | H33: F16-CF-415 Scavenger Flotation Cell 2 Gear Box Oil Temperature Transmitter | I33: F16CF415 G/Box Oil | J33: 1 | K33: -5 | L33: 300 | M33: °C | N33: 15 | O33: 5 | Q33: 23 | R33: 5 | T33: 55 | U33: 5 | W33: 65 | X33: 5 | AD33: 80 | AE33: 5 | AF33: 90 | AG33: 5 | AM33: Source: 2000-ME001.4-F16-50001 and 2000-ME001.4-M02-50001. Hysteresis of 5 degrees for Alarm High High. P_HH > F16-FN-501 turns on P_Hi < F16-FN-501 turns off P_Lo > F16-HT-570 and F16-HT-571 turns off P_LL < F16-HT-570 and F16-HT-571 turns on A_Hi > Alarm - inspection of gear unit required A_HH > F16-AG-425 trips | AN33: 1
E34: PT16095 | F34: PI16095 | G34: 2000-F16-PID-PR-10003 | H34: F16-CF-415 Scavenger Flotation Cell 2 Gear Box Oil Pressure Transmitter | I34: F16CF415 G/Box Oil | J34: 1 | K34: 0 | L34: 1600 | M34: kPa | Z34: 50 | AA34: 5 | AB34: 70 | AC34: 5 | AD34: 800 | AE34: 5 | AF34: 1000 | AG34: 5 | AM34: Source: 2000-ME001.4-M02-50001. A_HH > Unit shutdown. A_Hi > Alarm - inspection of gearbox required A_Lo < Alarm - inspection of gearbox required A_LL < Agitator Trip Alarm enabled delay of 10 seconds on start-up. | AN34: C
E35: PDIT16098 | F35: PDI16098 | G35: 2000-F16-PID-PR-10003 | H35: F16-CF-415 Scavenger Flotation Cell 2 Gear Box Filter Pressure Differential Transmitter | I35: F16CF415 G/Box Fltr Dlta | J35: 1 | K35: -100 | L35: 600 | M35: kPa(g) | AD35: 200 | AE35: 5 | AM35: Source: 2000-ME001.4-M02-50001. Alarm enabled delay of 10 seconds on agitator start-up. | AN35: 1
E36: VT16099 | F36: VI16099 | G36: 2000-F16-PID-PR-10003 | H36: F16-CF-415 Scavenger Flotation Cell 2 Gear Box Vibration Transmitter | I36: F16CF415 G/Box | J36: 1 | K36: 0 | L36: 15 | M36: mm/s | AD36: 8 | AE36: 5 | AF36: 12 | AG36: 5 | AM36: Source: 2000-ME001.4-M02-50001. Alarm enabled delay of 10 seconds on agitator start-up. | AN36: 1
E37: VT16100 | F37: VI16100 | G37: 2000-F16-PID-PR-10003 | H37: F16-CF-415 Scavenger Flotation Cell 2 Motor Vibration Transmitter | I37: F16CF415 Motor | J37: 1 | K37: 0 | L37: 15 | M37: mm/s | AD37: 4 | AE37: 5 | AF37: 7.1 | AG37: 5 | AM37: Source: 2000-ME001.4-M02-50001. Alarm enabled delay of 10 seconds on agitator start-up. | AN37: 1
E38: PIT16102 | F38: PI16102 | G38: 2000-F16-PID-PR-10003 | H38: F16-CF-416 Scavenger Flotation Cell 3 Low Pressure Air Pressure Indicating Transmitter | I38: F16CF416 Blower Air | J38: 1 | K38: 0 | L38: 500 | M38: kPa(g) | AB38: 90 | AC38: 5 | AD38: 130 | AE38: 5 | AL38: Duty F16BW401 AND 402 AND 403 AND 404 NOT RUNNING | AM38: Nominal pressure: 104.5 kPa(g) Maximum pressure: 119.7 kPa(g) Alarm setpoints to be confirmed during commissioning. Alarm enabled delay of 10 seconds during blower start-up. | AN38: 0
E39: TT16104 | F39: TI16104 | G39: 2000-F16-PID-PR-10003 | H39: F16-CF-416 Scavenger Flotation Cell 3 Gear Box Oil Temperature Transmitter | I39: F16CF416 G/Box Oil | J39: 1 | K39: -5 | L39: 300 | M39: °C | N39: 15 | O39: 5 | Q39: 23 | R39: 5 | T39: 55 | U39: 5 | W39: 65 | X39: 5 | AD39: 80 | AE39: 5 | AF39: 90 | AG39: 5 | AM39: Source: 2000-ME001.4-F16-50001 and 2000-ME001.4-M02-50001. Hysteresis of 5 degrees for Alarm High High. P_HH > F16-FN-502 turns on P_Hi < F16-FN-502 turns off P_Lo > F16-HT-572 and F16-HT-573 turns off P_LL < F16-HT-572 and F16-HT-573 turns on A_Hi > Alarm - inspection of gear unit required A_HH > F16-AG-426 trips | AN39: 1
E40: PT16105 | F40: PI16105 | G40: 2000-F16-PID-PR-10003 | H40: F16-CF-416 Scavenger Flotation Cell 3 Gear Box Oil Pressure Transmitter | I40: F16CF416 G/Box Oil | J40: 1 | K40: 0 | L40: 1600 | M40: kPa | Z40: 50 | AA40: 5 | AB40: 70 | AC40: 5 | AD40: 800 | AE40: 5 | AF40: 1000 | AG40: 5 | AM40: Source: 2000-ME001.4-M02-50001. A_HH > Unit shutdown. A_Hi > Alarm - inspection of gearbox required A_Lo < Alarm - inspection of gearbox required A_LL < Agitator Trip Alarm enabled delay of 10 seconds on start-up. | AN40: C
...

Sheet 2. Analogue Output
E1: =ProjectTitle -> KCGM GROWTH PROJECT
E2: ='Cover Page'!DocumentTitle -> PROCESS CONTROL TABLES - FLOTATION (F16, F17, F18)
E3: ='Cover Page'!A29 -> 2000-F16-LST-PR-10001
E4: ANALOGUE INSTRUMENTS (AO)
E5: Tag Source | F5: Tag Name | G5: P&ID | H5: Description | I5: Abbreviated Description (Faceplate) | K5: Range
A6: Area | B6: Type | C6: Loop No. | D6: Suffix | J6: Trend (sec) | K6: Min | L6: Max | M6: Unit | N6: Comments | O6: Rev
E7: ZC16001 | F7: ZY16001 | G7: 2000-F16-PID-PR-10001 | H7: F16-CF-411 Rougher Flotation Cell 1 Process Water Flow Control Valve Position Control | I7: F16CF411 PW FCV | J7: 1 | K7: 0 | L7: 100 | M7: % | O7: 2
E8: ZC17130 | F8: ZY17130 | G8: 2000-F17-PID-PR-10002 | H8: F17-PP-455/456 Flotation Tailings Thickener Underflow Pump 1/2 Discharge to Final Tails Tank | I8: F17TH401 UF - FinalTails | J8: 1 | K8: 0 | L8: 100 | M8: % | O8: 2
E9: DO NOT DELETE THIS ROW INSERT NEW ROWS ABOVE
E11: =COUNTA(E7:E8) -> 2 | F11: =COUNTA(F7:F8) -> 2

Sheet 3. Digital Input
E1: KCGM GROWTH PROJECT
E2: PROCESS CONTROL TABLES - FLOTATION (F16, F17, F18) | J2: *SOFTWARE DEBOUNCE IS REQUIRED ON ALL DIGITAL INSTRUMENTS (NO HARDWARE DEBOUNCE)*
E3: 2000-F16-LST-PR-10001
E4: DIGITAL INSTRUMENTS (DI)
A6: Area | B6: Type | C6: Loop No. | D6: Suffix | E6: Tag Source | F6: Tag Name | G6: P&ID | H6: Description | I6: Abbreviated Description (Faceplate) | J6: State 0 | K6: State 1 | L6: Alarm State | M6: Source | N6: Alarm Priority | O6: Alarm Delay (secs) | P6: Alarm Masking Conditions | Q6: Comments | R6: Rev
E7: F18RIO001PS2 | F7: F18RIO001_PS2 | G7: 2000-F18-PID-PR-10001 | H7: F18-RIO-001 PS2 24VDC HEALTHY | I7: F18RIO001 PS2 24VDC | J7: Alarm | K7: Normal | L7: Alarm | M7: Hardwired | O7: 0 | R7: 2
E8: F18RIO001PS1 | F8: F18RIO001_PS1 | G8: 2000-F18-PID-PR-10001 | H8: F18-RIO-001 PS1 24VDC HEALTHY | I8: F18RIO001 PS1 24VDC | J8: Alarm | K8: Normal | L8: Alarm | M8: Hardwired | O8: 0 | R8: 2
E9: ZS17010 | F9: ZA17010 | G9: 2000-F17-PID-PR-10001 | H9: F17-TH-401 Flotation Tailings Thickener Rake Drive Position Switch | I9: F17TH401 Thickener Rake | J9: Off | K9: On | M9: Hardwired | R9: 2
E10: F17RIO002PS2 | F10: F17RIO002_PS2 | G10: 2000-F17-PID-PR-10001 | H10: F17-RIO-002 PS2 24VDC HEALTHY | I10: F17RIO002 PS2 24VDC | J10: Alarm | K10: Normal | L10: Alarm | M10: Hardwired | O10: 0 | R10: 2
E11: F17RIO002PS1 | F11: F17RIO002_PS1 | G11: 2000-F17-PID-PR-10001 | H11: F17-RIO-002 PS1 24VDC HEALTHY | I11: F17RIO002 PS1 24VDC | J11: Alarm | K11: Normal | L11: Alarm | M11: Hardwired | O11: 0 | R11: 2
E12: F16RIO002PS2 | F12: F16RIO002_PS2 | G12: 2000-F16-PID-PR-10001 | H12: F16-RIO-002 PS2 24VDC HEALTHY | I12: F16RIO002 PS2 24VDC | J12: Alarm | K12: Normal | L12: Alarm | M12: Hardwired | O12: 0 | R12: 2
E13: F16RIO002PS1 | F13: F16RIO002_PS1 | G13: 2000-F16-PID-PR-10001 | H13: F16-RIO-002 PS1 24VDC HEALTHY | I13: F16RIO002 PS1 24VDC | J13: Alarm | K13: Normal | L13: Alarm | M13: Hardwired | O13: 0 | R13: 2
E14: F16SW104Q1TRP | F14: F16SW104Q1_TR | G14: 2000-F16-PID-PR-10001 | H14: F16-SW-104 Mains Supply CB Tripped | I14: F16SW104 Breaker Trip | J14: Alarm | K14: Normal | L14: Alarm | M14: Hardwired | O14: 0 | R14: 2
E15: F16SW104Q1CL | F15: F16SW104_Q1CL | G15: 2000-F16-PID-PR-10001 | H15: F16-SW-104 Mains Supply CB Closed | I15: F16SW104 Breaker Closed | J15: Alarm | K15: Normal | M15: Hardwired | R15: 2
E16: F16SW104SD | F16: F16SW104_SD | G16: 2000-F16-PID-PR-10001 | H16: F16-SW-104 Surge Diverter Ok | I16: F16SW104 Surge Diverter | J16: Alarm | K16: Normal | L16: Alarm | M16: Hardwired | O16: 0 | R16: 2
E17: F16SW011OP | F17: F16SW011_OP | G17: N/A | H17: Flotation 11kV Switchboard Remote Switching Panel Breaker Opened | I17: Flot 11kV SB Rem Break O | J17: Alarm | K17: Normal | M17: Hardwired | R17: 2
E18: F16SW011CL | F18: F16SW011_CL | G18: N/A | H18: Flotation 11kV Switchboard Remote Switching Panel Breaker Closed | I18: Flot 11kV SB Rem Break C | J18: Alarm | K18: Normal | M18: Hardwired | R18: 2
E19: F16SR001ESTP | F19: F16SR001_ESTP | G19: N/A | H19: Flotation 11kV Switchroom Emergency Shutdown Healthy | I19: Flot 11kV SR E Shut | J19: Alarm | K19: Normal | L19: Alarm | M19: Hardwired | O19: 0 | R19: 2
E20: F16FIP002ISL | F20: F16FIP002_ISL | G20: 2000-F16-PID-PR-10001 | H20: F16-FIP-002 Isolated | I20: F16FIP002 Isolate | J20: Alarm | K20: Normal | L20: Alarm | M20: Hardwired | O20: 0 | R20: 2
E21: F17RIO001PS2 | F21: F17RIO001_PS2 | G21: 2000-F16-PID-PR-10001 | H21: F17-RIO-001 PS2 24VDC HEALTHY | I21: F17RIO002 PS1 24VDC | J21: Alarm | K21: Normal | L21: Alarm | M21: Hardwired | O21: 0 | R21: 2
E22: F16SW104Q2CL | F22: F16SW104_Q2CL | G22: 2000-F16-PID-PR-10001 | H22: F16-SW-104 Generator Supply CB Closed | I22: F16SW104 Gen CB Closed | J22: Alarm | K22: Normal | M22: Hardwired | R22: 2
E23: F17RIO001PS1 | F23: F17RIO001_PS1 | G23: 2000-F16-PID-PR-10001 | H23: F17-RIO-001 PS1 24VDC HEALTHY | I23: F17RIO001 PS1 24VDC | J23: Alarm | K23: Normal | L23: Alarm | M23: Hardwired | O23: 0 | R23: 2
E24: F16AN403S2XRS | F24: F16AN403S2XR | G24: 2000-F16-PID-PR-10006 | H24: F16-AN-403 Onstream Sulphur Analyser Stream 2 Sample X-Ray Active | I24: F16AN403 S2 X-Ray | J24: Inactive | K24: Active | M24: Softag | Q24: Status bit = 07 Bit map for analyser status word. Tag naming convention to be replicated for all streams. Refer to 2000-SPC-CS-11001 Onstream Sulphur Analyser Modbus Map for details. | R24: 2
E25: F16AN403S3XRS | F25: F16AN403S3XR | G25: 2000-F16-PID-PR-10007 | H25: F16-AN-403 Onstream Sulphur Analyser Stream 3 Sample X-Ray Active | I25: F16AN403 S3 X-Ray | J25: Inactive | K25: Active | M25: Softag | Q25: Status bit = 07 Bit map for analyser status word. Tag naming convention to be replicated for all streams. Refer to 2000-SPC-CS-11001 Onstream Sulphur Analyser Modbus Map for details. | R25: 2
E26: F16AN403S1XRS | F26: F16AN403S1XR | G26: 2000-F16-PID-PR-10005 | H26: F16-AN-403 Onstream Sulphur Analyser Stream 1 Sample X-Ray Active | I26: F16AN403 S1 X-Ray | J26: Inactive | K26: Active | M26: Softag | Q26: Status bit = 07 Bit map for analyser status word. Tag naming convention to be replicated for all streams. Refer to 2000-SPC-CS-11001 Onstream Sulphur Analyser Modbus Map for details. | R26: 2
E27: F16AN403S1MRS | F27: F16AN403S1MR | G27: 2000-F16-PID-PR-10005 | H27: F16-AN-403 Onstream Sulphur Analyser Stream 1 Sample Measurement Result Not Ok | I27: F16AN403 S1 Results Flt | J27: Inactive | K27: Active | L27: Active | M27: Softag | O27: 3 | Q27: Status bit = 08 Bit map for analyser status word. Tag naming convention to be replicated for all streams. Refer to 2000-SPC-CS-11001 Onstream Sulphur Analyser Modbus Map for details. | R27: 2
E28: F16AN403S12XS | F28: F16AN403S12XR | G28: 2000-F16-PID-PR-10016 | H28: F16-AN-403 Onstream Sulphur Analyser Stream 12 Sample X-Ray Active | I28: F16AN403 S12 X-Ray | J28: Inactive | K28: Active | M28: Softag | Q28: Status bit = 07 Bit map for analyser status word. Tag naming convention to be replicated for all streams. Refer to 2000-SPC-CS-11001 Onstream Sulphur Analyser Modbus Map for details. | R28: 2
E29: F16AN403S11XS | F29: F16AN403S11XR | G29: 2000-F16-PID-PR-10015 | H29: F16-AN-403 Onstream Sulphur Analyser Stream 11 Sample X-Ray Active | I29: F16AN403 S11 X-Ray | J29: Inactive | K29: Active | M29: Softag | Q29: Status bit = 07 Bit map for analyser status word. Tag naming convention to be replicated for all streams. Refer to 2000-SPC-CS-11001 Onstream Sulphur Analyser Modbus Map for details. | R29: 2
E30: F16AN403S4MRS | F30: F16AN403S4MR | G30: 2000-F16-PID-PR-10008 | H30: F16-AN-403 Onstream Sulphur Analyser Stream 4 Sample Measurement Result Not Ok | I30: F16AN403 S4 Results Flt | J30: Inactive | K30: Active | L30: Active | M30: Softag | O30: 3 | Q30: Status bit = 08 Bit map for analyser status word. Tag naming convention to be replicated for all streams. Refer to 2000-SPC-CS-11001 Onstream Sulphur Analyser Modbus Map for details. | R30: 2
E31: F16AN403S3MRS | F31: F16AN403S3MR | G31: 2000-F16-PID-PR-10007 | H31: F16-AN-403 Onstream Sulphur Analyser Stream 3 Sample Measurement Result Not Ok | I31: F16AN403 S3 Results Flt | J31: Inactive | K31: Active | L31: Active | M31: Softag | O31: 3 | Q31: Status bit = 08 Bit map for analyser status word. Tag naming convention to be replicated for all streams. Refer to 2000-SPC-CS-11001 Onstream Sulphur Analyser Modbus Map for details. | R31: 2
E32: F16AN403S9XRS | F32: F16AN403S9XR | G32: 2000-F16-PID-PR-10013 | H32: F16-AN-403 Onstream Sulphur Analyser Stream 9 Sample X-Ray Active | I32: F16AN403 S9 X-Ray | J32: Inactive | K32: Active | M32: Softag | Q32: Status bit = 07 Bit map for analyser status word. Tag naming convention to be replicated for all streams. Refer to 2000-SPC-CS-11001 Onstream Sulphur Analyser Modbus Map for details. | R32: 2
E33: F16AN403S10XS | F33: F16AN403S10XR | G33: 2000-F16-PID-PR-10014 | H33: F16-AN-403 Onstream Sulphur Analyser Stream 10 Sample X-Ray Active | I33: F16AN403 S10 X-Ray | J33: Inactive | K33: Active | M33: Softag | Q33: Status bit = 07 Bit map for analyser status word. Tag naming convention to be replicated for all streams. Refer to 2000-SPC-CS-11001 Onstream Sulphur Analyser Modbus Map for details. | R33: 2
E34: F16AN403S6XRS | F34: F16AN403S6XR | G34: 2000-F16-PID-PR-10010 | H34: F16-AN-403 Onstream Sulphur Analyser Stream 6 Sample X-Ray Active | I34: F16AN403 S6 X-Ray | J34: Inactive | K34: Active | M34: Softag | Q34: Status bit = 07 Bit map for analyser status word. Tag naming convention to be replicated for all streams. Refer to 2000-SPC-CS-11001 Onstream Sulphur Analyser Modbus Map for details. | R34: 2
E35: F16AN403S4XRS | F35: F16AN403S4XR | G35: 2000-F16-PID-PR-10008 | H35: F16-AN-403 Onstream Sulphur Analyser Stream 4 Sample X-Ray Active | I35: F16AN403 S4 X-Ray | J35: Inactive | K35: Active | M35: Softag | Q35: Status bit = 07 Bit map for analyser status word. Tag naming convention to be replicated for all streams. Refer to 2000-SPC-CS-11001 Onstream Sulphur Analyser Modbus Map for details. | R35: 2
E36: F16AN403S5XRS | F36: F16AN403S5XR | G36: 2000-F16-PID-PR-10009 | H36: F16-AN-403 Onstream Sulphur Analyser Stream 5 Sample X-Ray Active | I36: F16AN403 S5 X-Ray | J36: Inactive | K36: Active | M36: Softag | Q36: Status bit = 07 Bit map for analyser status word. Tag naming convention to be replicated for all streams. Refer to 2000-SPC-CS-11001 Onstream Sulphur Analyser Modbus Map for details. | R36: 2
E37: F16AN403S7XRS | F37: F16AN403S7XR | G37: 2000-F16-PID-PR-10011 | H37: F16-AN-403 Onstream Sulphur Analyser Stream 7 Sample X-Ray Active | I37: F16AN403 S7 X-Ray | J37: Inactive | K37: Active | M37: Softag | Q37: Status bit = 07 Bit map for analyser status word. Tag naming convention to be replicated for all streams. Refer to 2000-SPC-CS-11001 Onstream Sulphur Analyser Modbus Map for details. | R37: 2
E38: F16AN403S8XRS | F38: F16AN403S8XR | G38: 2000-F16-PID-PR-10012 | H38: F16-AN-403 Onstream Sulphur Analyser Stream 8 Sample X-Ray Active | I38: F16AN403 S8 X-Ray | J38: Inactive | K38: Active | M38: Softag | Q38: Status bit = 07 Bit map for analyser status word. Tag naming convention to be replicated for all streams. Refer to 2000-SPC-CS-11001 Onstream Sulphur Analyser Modbus Map for details. | R38: 2
E39: F16AN403S12AS | F39: F16AN403S12AV | G39: 2000-F16-PID-PR-10016 | H39: F16-AN-403 Onstream Sulphur Analyser Stream 12 Sample Analysis Values Not Ok | I39: F16AN403 S12 AnalysisFlt | J39: Inactive | K39: Active | L39: Active | M39: Softag | O39: 3 | Q39: Status bit = 09 Bit map for analyser status word. Tag naming convention to be replicated for all streams. Refer to 2000-SPC-CS-11001 Onstream Sulphur Analyser Modbus Map for details. | R39: 2
E40: F16AN403S10AS | F40: F16AN403S10AV | G40: 2000-F16-PID-PR-10014 | H40: F16-AN-403 Onstream Sulphur Analyser Stream 10 Sample Analysis Values Not Ok | I40: F16AN403 S10 AnalysisFlt | J40: Inactive | K40: Active | L40: Active | M40: Softag | O40: 3 | Q40: Status bit = 09 Bit map for analyser status word. Tag naming convention to be replicated for all streams. Refer to 2000-SPC-CS-11001 Onstream Sulphur Analyser Modbus Map for details. | R40: 2
E41: F16AN403S11AS | F41: F16AN403S11AV | G41: 2000-F16-PID-PR-10015 | H41: F16-AN-403 Onstream Sulphur Analyser Stream 11 Sample Analysis Values Not Ok | I41: F16AN403 S11 AnalysisFlt | J41: Inactive | K41: Active | L41: Active | M41: Softag | O41: 3 | Q41: Status bit = 09 Bit map for analyser status word. Tag naming convention to be replicated for all streams. Refer to 2000-SPC-CS-11001 Onstream Sulphur Analyser Modbus Map for details. | R41: 2
...

Sheet 4. Digital Output
E1: KCGM GROWTH PROJECT
E2: PROCESS CONTROL TABLES - FLOTATION (F16, F17, F18) | J2: *SOFTWARE DEBOUNCE IS REQUIRED ON ALL DIGITAL INSTRUMENTS (NO HARDWARE DEBOUNCE)*
E3: 2000-F16-LST-PR-10001
E4: DIGITAL INSTRUMENTS (DO)
A6: Area | B6: Type | C6: Loop No. | D6: Suffix | E6: Tag Source | F6: Tag Name | G6: P&ID | H6: Description | I6: Abbreviated Description (Faceplate) | J6: State 0 | K6: State 1 | L6: Alarm State | M6: Alarm Delay (secs) | N6: Alarm Masking Conditions | O6: Comments | P6: Rev
E7: XY17066 | F7: XI17066 | G7: 2000-F17-PID-PR-10001 | H7: F17TH401-CP Flotation Tailings Thickener Control Panel 24VDC Power Healthy Indicator Light | I7: F17TH401 Pwr Healthy | J7: Alarm | K7: Normal | L7: Alarm | M7: 0 | O7: 24V DCS Power Healthy | P7: 2
E8: YI17117A | F8: YA17117A | G8: 2000-F17-PID-PR-10002 | H8: F17-FN-504 Flotation Tailings Thickener Underflow Tunnel Ventilation Fan Not Running Signal 1 | I8: F17FN504 Not Running 1 | J8: Normal | K8: Activated | M8: 0 | O8: Activate when: - F17FN504 Not Running Digital output to activate two beacons and sirens located inside the Flotation Tailings Thickener Underflow Tunnel. | P8: 1
E9: YI17117B | F9: YA17117B | G9: 2000-F17-PID-PR-10002 | H9: F17-FN-504 Flotation Tailings Thickener Underflow Tunnel Ventilation Fan Not Running Signal 2 | I9: F17FN504 Not Running 2 | J9: Normal | K9: Activated | M9: 0 | O9: Activate when: - F17FN504 Not Running Digital output to activate two beacons and sirens located inside the Flotation Tailings Thickener Underflow Tunnel. | P9: 1
E10: XY17076 | F10: XC17076 | G10: 2000-F17-PID-PR-10001 | H10: F17TH401-CP Flotation Tailings Thickener Control Panel Rake Drive Running Status to LCP Control Signal | I10: F17TH401 Rake Drive Rng | J10: Normal | K10: Activated | M10: 0 | O10: Source: 2000-ME001.5-F17-50001. Activate when F17PO408 = RUNNING | P10: 2
E11: XY17079 | F11: XC17079 | G11: 2000-F17-PID-PR-10001 | H11: F17TH401-CP Flotation Tailings Thickener Control Panel 85% Torque Request frrom DCS to LCP Control Signal | I11: F17TH401 85% Torque | J11: Normal | K11: Activated | L11: NI17030 >= A_HH == TRUE | M11: 0 | O11: Activate on NI17030 >= A_HH. Source: 2000-ME001.5-F17-50001. Must activate Torque Cut - Out on LCP - XI17030A. | P11: 2
E12: XY17083 | F12: XC17083 | G12: 2000-F17-PID-PR-10001 | H12: F17TH401-CP Flotation Tailings Thickener Control Panel 50% Torque Request frrom DCS to LCP Control Signal | I12: F17TH401 50% Torque | J12: Normal | K12: Activated | L12: NI17030 >= A_Hi == TRUE | M12: 0 | O12: Activate on NI17030 A_Hi. Source: 2000-ME001.5-F17-50001. | P12: 2
E13: XY17080 | F13: XC17080 | G13: 2000-F17-PID-PR-10001 | H13: F17TH401-CP Flotation Tailings Thickener Control Panel 40% Torque Request frrom DCS to LCP Control Signal | I13: F17TH401 40% Torque | J13: Normal | K13: Activated | L13: NI17030 >= P_Hi == TRUE | M13: 0 | O13: Activate on NI17030 >= P_Hi. Will activate horn and beacon. Source: 2000-ME001.5-F17-50001. | P13: 2
E14: XY17084 | F14: XC17084 | G14: 2000-F17-PID-PR-10001 | H14: F17TH401-CP Flotation Tailings Thickener Control Panel 30% Torque Request frrom DCS to LCP Control Signal | I14: F17TH401 30% Torque | J14: Normal | K14: Activated | L14: NI17030 <= P_Lo == TRUE | M14: 0 | O14: Activate on NI18030 P_Lo. Source: 2000-ME001.5-F17-50001. | P14: 2
E15: XY17062 | F15: XC17062 | G15: 2000-F17-PID-PR-10001 | H15: F17TH401-CP Flotation Tailings Thickener Control Panel Reverse Jog Enable Feedback | I15: F17TH401 Rev Jog Enable | J15: Normal | K15: Activated | M15: 0 | O15: Source: 2000-ME001.5-F17-50001. Activate when: Control Room Operator selects button in DCS "Reverse Jog Enable" (F17TH401_REV Active). Clicking this button will activate XC17057 and place the following equipment in LOCAL (F17TH401_LCL Active): - F17PO408, SV17033, SV17034 - F17PO409, SV17047, SV17048 Please refer to 12. Misc for further details on F17TH401 LOCAL mode. | P15: 2
E16: XY17057 | F16: XC17057 | G16: 2000-F17-PID-PR-10001 | H16: F17TH401-CP Flotation Tailings Thickener Control Panel Local Mode Enable Feedback | I16: F17TH401 Local Mode | J16: Disabled | K16: Enabled | M16: 0 | O16: Source: 2000-ME001.5-F17-50001. Activate when: Thickener Faceplate placed into Local mode in DCS. F17TH401 to be constructed as a singular object. Placing into LOCAL mode will place the following equipment into LOCAL (F17TH401_LCL Active): - F17PO408, SV17033, SV17034 - F17PO409, SV17047, SV17048 Please refer to 12. Misc for further details on F17TH401 LOCAL mode. | P16: 2
E17: XY17082 | F17: XC17082 | G17: 2000-F17-PID-PR-10001 | H17: F17TH401-CP Flotation Tailings Thickener Control Panel Horn Acknowledge Control Signal | I17: F17TH401 Horn Ackwldge | J17: Normal | K17: Activated | M17: 0 | O17: Source: 2000-ME001.5-F17-50001. Horn is activated on torque level greater than 40% by XC17080. Horn will continue to sound until physical switch is depressed on local control board or a graphical user-interface button "Horn Acknowledge" is pressed by Control Room Operator. Clicking graphical user-interface button will de-activate horn via activation of this digital output. | P17: 2
E18: HS17038 | F18: HS17038STT | G18: 2000-F17-PID-PR-10001 | H18: F17XM572 Manta Sub Start/Stop Command | I18: F17XM572 Manta Run | J18: N_Running | K18: Running | M18: 0 | O18: Soft-tag. Modbus connection to Manta Sub PLC. Manta Sub Documentation: 2000-ME001.5-D02-50002 | P18: 2
E19: F17XM572CSTTS | F19: HS17038STT | G19: 2000-F17-PID-PR-10001 | H19: F17XM572 Manta Sub Communication Start | I19: F17XM572 Remote Start | J19: Inactive | K19: Start | O19: SoftTag Manta Ref: Manta_Sub.CommsStSta Details TBC by vendor. Refer to Manta Sub Modbus Tags Register Without Thickener Cube (05-REG-500) | P19: 2
E20: F17XM572STPS | F20: HS17038STP | G20: 2000-F17-PID-PR-10001 | H20: F17XM572 Manta Sub Exetrnal Stop Request | I20: F17XM572 Remote Stop | J20: Inactive | K20: Stop | O20: SoftTag Manta Ref: Manta_Sub.ExtStopRequest Details TBC by vendor. Refer to Manta Sub Modbus Tags Register Without Thickener Cube (05-REG-500) | P20: 2
E21: F16SW011OP1 | F21: F16SW011_OP1 | G21: N/A | H21: Flotation 11kV Switchboard Remote Switching Panel Open Breaker Incomer 1 | I21: Flot 11kV Rem O Break1 | J21: Normal | K21: Activated | M21: 0 | P21: 2
E22: F16SW011CL1 | F22: F16SW011_CL1 | G22: N/A | H22: Flotation 11kV Switchboard Remote Switching Panel Close Breaker Incomer 1 | I22: Flot 11kV Rem C Break1 | J22: Normal | K22: Activated | M22: 0 | P22: 2
E23: F16SW011OP2 | F23: F16SW011_OP2 | G23: N/A | H23: Flotation 11kV Switchboard Remote Switching Panel Open Breaker Incomer 2 | I23: Flot 11kV Rem O Break2 | J23: Normal | K23: Activated | M23: 0 | P23: 2
E24: F16SW011CL2 | F24: F16SW011_CL2 | G24: N/A | H24: Flotation 11kV Switchboard Remote Switching Panel Close Breaker Incomer 2 | I24: Flot 11kV Rem C Break2 | J24: Normal | K24: Activated | M24: 0 | P24: 2
E25: DO NOT DELETE THIS ROW INSERT NEW ROWS ABOVE
E28: =COUNTA(E8:E24) -> 17 | F28: =COUNTA(F8:F24) -> 17

Sheet 5. Totalisers
E1: KCGM GROWTH PROJECT
E2: PROCESS CONTROL TABLES - FLOTATION (F16, F17, F18)
E3: 2000-F16-LST-PR-10001
E4: TOTALISERS
L5: Reset Period
A6: Area | B6: Type | C6: Loop No. | D6: Suffix | E6: Tag Source | F6: Tag Name | G6: Type | H6: P&ID | I6: Description | J6: Abbreviated Description (Faceplate) | K6: Units | L6: Shift | M6: Day | N6: Cont | O6: Comments | P6: Rev
E7: WI17121 | F7: WQI17121 | G7: WQI | H7: 2000-F17-PID-PR-10002 | I7: F17-PP-455/456 Flotation Tailings Thickener Underflow Pumps Solids Mass Totaliser | J7: F17TH401 U/F Solids Mass | K7: t/h | L7: X | M7: X | N7: X | P7: B
E8: WI17130 | F8: WQI17130 | G8: WQI | H8: 2000-F17-PID-PR-10002 | I8: F17-PP-455/456 Flotation Tailings Thickener Underflow to Final Tails Tank Solids Mass Totaliser | J8: F17TH401 UF-Final Tails | K8: t/h | L8: X | M8: X | N8: X | O8: See 11. Calculation sheet for further information. | P8: B
E9: WI18027 | F9: WQI18027 | G9: WQI | H9: 2000-F18-PID-PR-10001 | I9: F18-PP-407/408 Final Concentrate Pumps Discharge Solids Mass Totaliser | J9: F18PP407/8 Solids Mass | K9: t/h | L9: X | M9: X | N9: X | P9: B
E10: WI18237 | F10: WQI18237 | G10: WQI | H10: 2000-F18-PID-PR-10003 | I10: F18-PP-407/408 Final Concentrate Pumps Discharge Solids Mass Totaliser | J10: F18PP513/4 Solids Mass | K10: t/h | L10: X | M10: X | N10: X | P10: B
E11: DO NOT DELETE THIS ROW INSERT NEW ROWS ABOVE
E15: 4 | F15: 4

Sheet 6. OnOff Valves
E1: KCGM GROWTH PROJECT
E2: PROCESS CONTROL TABLES - FLOTATION (F16, F17, F18)
E3: 2000-F16-LST-PR-10001
E4: OPEN-CLOSE VALVES
O5: Permissives and Trips
A6: Area | B6: Type | C6: Loop No. | D6: Suffix | E6: Tag Name | F6: P&ID | G6: Valve Description | H6: Abbreviated Description (Faceplate) | I6: Valve Type | J6: Fail Position (Loss of Power) | K6: Manual | L6: Auto | M6: Open Condition (Auto Mode) | N6: Close Condition (Auto Mode) | O6: # | P6: Condition | Q6: Description (Faceplate) | R6: Delay On | S6: Delay Off | T6: Open Permissive | U6: Close Permissive | V6: Open Interlock | W6: Close Interlock | X6: Bypass | Y6: Reset Required | Z6: Comments | AA6: Rev
E7: XV16025 | F7: 2000-F16-PID-PR-10001 | G7: F16-GA-425 Rougher 1 Concentrate Cleaner Feed Launder Gate Cleaner Flotation Feed Valve | H7: F16GA425 Rgh1 Clnr Con | I7: Detail 3 | J7: FL | K7: X | M7: Manually opened by Operator | N7: Manually closed by Operator | AA7: B
E9: XV16026 | F9: 2000-F16-PID-PR-10001 | G9: F16-GA-426 Rougher 1 Final Concentrate Launder Gate Final Concentrate Feed Valve | H9: F16GA426 Rgh1 Final Con | I9: Detail 3 | J9: FL | K9: X | M9: Manually opened by Operator | N9: Manually closed by Operator | AA9: B
E11: SV16357 | F11: 2000-F24-PID-PR-10003 | G11: F16-PP-515 Flotation Cells Drain Pump Gland Water Solenoid Valve | H11: F16PP515 Gland Supply | I11: Detail 11 | J11: FO | K11: X | M11: Manually opened by Operator | N11: Manually closed by Operator | O11: OT1 | P11: F16PP515 RUNNING | Q11: Flotation Cells Drain Pump Rung | R11: 0 | V11: X | AA11: C
E13: XV16152 | F13: 2000-F16-PID-PR-10005 | G13: F16-PP-638 Sample Return Pump 1 Suction Valve | H13: F16PP638 Suction | I13: Detail 3 | J13: FL | K13: X | M13: Manually opened by Operator | N13: Manually closed by Operator | AA13: B
E15: XV16153 | F15: 2000-F16-PID-PR-10005 | G15: F16-PP-638 Sample Return Pump 1 Drain Valve | H15: F16PP638 Suction Drain | I15: Detail 4 | J15: FO | K15: X | M15: Manually opened by Operator | N15: Manually closed by Operator | O15: CT1 | P15: F16PP638 RUNNING | Q15: Sample Return Pump 1 is Running | R15: 3 | W15: X | AA15: 2
E17: SV16155 | F17: 2000-F24-PID-PR-10003 | G17: F16-PP-638 Sample Return Pump 1 Gland Water Solenoid Valve | H17: F16PP638 Gland Supply | I17: Detail 11 | J17: FO | K17: X | M17: Manually opened by Operator | N17: Manually closed by Operator | O17: OT1 | P17: F16PP638 RUNNING | Q17: Sample Return Pump 1 is Running | R17: 0 | V17: X | AA17: B
E19: XV16162 | F19: 2000-F16-PID-PR-10005 | G19: F16-PP-639 Sample Return Pump 2 Suction Valve | H19: F16PP639 Suction | I19: Detail 3 | J19: FL | K19: X | M19: Manually opened by Operator | N19: Manually closed by Operator | AA19: B
E21: XV16163 | F21: 2000-F16-PID-PR-10005 | G21: F16-PP-639 Sample Return Pump 2 Suction Drain Valve | H21: F16PP639 Suction Drain | I21: Detail 4 | J21: FO | K21: X | M21: Manually opened by Operator | N21: Manually closed by Operator | O21: CT1 | P21: F16PP639 RUNNING | Q21: Sample Return Pump 2 is Running | R21: 3 | W21: X | AA21: 2
E23: SV16165 | F23: 2000-F24-PID-PR-10003 | G23: F16-PP-639 Sample Return Pump 2 Gland Water Solenoid Valve | H23: F16PP639 Gland Supply | I23: Detail 11 | J23: FO | K23: X | M23: Manually opened by Operator | N23: Manually closed by Operator | O23: OT1 | P23: F16PP639 RUNNING | Q23: Sample Return Pump 2 is Running | R23: 0 | V23: X | Z23: Shorter than Drive Interlock to maintain operation. | AA23: B
E25: XV17005 | F25: 2000-F17-PID-PR-10001 | G25: F16-PP-634 Final Tails Sample Pump Suction Valve | H25: F16PP634 Suction | I25: Detail 3 | J25: FL | K25: X | M25: Manually opened by Operator | N25: Manually closed by Operator | AA25: B
E27: XV17006 | F27: 2000-F17-PID-PR-10001 | G27: F16-PP-634 Final Tails Sample Pump Suction Drain Valve | H27: F16PP634 Suction Drain | I27: Detail 7 | J27: FO | K27: X | M27: Manually opened by Operator | N27: Manually closed by Operator | O27: CT1 | P27: F16PP634 RUNNING | Q27: Final Tails Sample Pump Running | R27: 3 | W27: X | AA27: 2
E29: XV17007 | F29: 2000-F17-PID-PR-10001 | G29: F16-PP-634 Final Tails Sample Pump Discharge Drain Valve | H29: F16PP634 Discharge Drain | I29: Detail 7 | J29: FO | K29: X | M29: Manually opened by Operator | N29: Manually closed by Operator | AA29: C
E31: XV17009 | F31: 2000-F17-PID-PR-10001 | G31: F17-BX-410 Flotation Tailings Thickener Recirculation Feed Box Feed Valve | H31: F17BX410 Feed Valve | I31: Detail 5 | J31: FL | K31: X | M31: Manually opened by Operator | N31: Manually closed by Operator | AA31: 0
E33: SV17033 | F33: 2000-F17-PID-PR-10001 | G33: F17-HU-406 Flotation Tailings Thickener Rake Drive HPU Rake Forward Solenoid Valve | H33: F17HU406 Rake Forward | I33: Vendor | J33: Rexroth | L33: X | M33: F18-SEQ-0003 | N33: F17TH401_STOP | O33: OP1 | P33: SV17034 NOT ENERGISED | Q33: Rev Solenoid N_Energised | R33: 3 | T33: X | Z33: DCS user-interface button "Stop Thickener in Forward Mode" when activated will de-energise SV17033. | AA33: 2
M34: F17TH401_STRT Active | N34: F17TH401_REV Active. | O34: CT1 | P34: XA17038 Active | Q34: Manta Sub Not in Home Posn | R34: 3 | W34: X | X34: X | Z34: Manta Sub Sensor not returned to home position. Thickener rakes will stop to prevent sensor contacting with rakes. DCS user-interface button "Enable Reverse Jog Mode in LOCAL" will de-energise SV17033 if activated AND start F17TH401_T3. Please see 12. Misc for further information. | AA34: 2
M35: F17TH401_LCL Active AND HS17061 Start Button Pressed AND F17TH401_REV Not Active | N35: F17TH401_LCL Active AND HS17064 Stop Button Active | O35: CT2 | P35: SSL17016 Alarm | Q35: F17TH401 Zero Speed Active | R35: 3 | U35: X | X35: X | Z35: Zero speed switch active. | AA35: 2
E37: SV17034 | F37: 2000-F17-PID-PR-10001 | G37: F17-HU-406 Flotation Tailings Thickener Rake Drive HPU Rake Reverse Solenoid Valve | H37: F17HU406 Rake Reverse | I37: Vendor | J37: Rexroth | L37: X | M37: F17TH401_LCL Active AND HS17063 Reverse Jog Button Active AND F17TH401_REV Active AND F17TH401_T3 Not Active AND F17TH401_T2 Not Active | N37: F17TH401_T1 Elapsed | O37: OP1 | P37: SV17033 NOT ENERGISED | Q37: Fwd Solenoid N_Energised | R37: 3 | T37: X | Z37: HS17063 must be depressed (active) for SV17034 to remain energised when in LOCAL mode. When SV17034 is energised, F17TH401_T1 is started. Maximum energised duration applies as per timer. Please refer to 12. Misc for further details. Reverse Enable must be Active to Energise Solenoid. Please refer to 12. Misc - F17TH401_REV for further details. | AA37: 2
N38: F17TH401_LCL Active AND HS17063 Released (Falling Edge) | O38: OP2 | P38: F17TH401_C1 < 3 | Q38: Reverse Jog Hourly Limit | R38: 0 | T38: X | Z38: Source: 2000-ME001.5-M02-50001. See 12. Misc for further details. | AA38: C
O39: OP3 | P39: F17TH401_T2 Not Active | Q39: Reverse Lockout Timer Active | R39: 0 | T39: X | Z39: Source: 2000-ME001.5-M02-50001. See 12. Misc for further details. | AA39: C
E41: SV17047 | F41: 2000-F17-PID-PR-10001 | G41: F17-HU-414 Flotation Tailings Thickener Rake Lift HPU Lower Rake Solenoid Valve | H41: F17HU414 Rake Lower | I41: Vendor | J41: Rexroth | L41: X | M41: AUTO MODE Active AND NI17030 < P_Lo AND SV17033 Energised AND F17PO408 Running AND F17TH401_REVC = 0 AND ZAL17015 Not Active AND F17PO409 Running (Runtime > 5 seconds) | N41: AUTO MODE Active AND F17TH401_RLWR Elapsed | O41: OP1 | P41: SV17048 NOT ACTIVE | R41: 3 | T41: X | Z41: Start F17TH401_RLWR when SV17047 Energised AND in AUTO MODE. To open solenoid in AUTO MODE: - NI17030 must be less than 30% - Thickener must be in FORWARD MODE - Revolution Counter must be equal to zero - Rake Low Limit Switch Not Active Control logic to be continually running when Thickener is in FORWARD MODE. Control logic to de-energise solenoid valve if during lowering in AUTO MODE, ZAL17015 becomes active. | AA41: 2
M42: F17TH401_LCL Active AND HS17065B Active | N42: F17TH401_LCL Active AND HS17065B Released (Falling Edge) | O42: OP2 | P42: AUTO MODE: F17-PO-408 RUNNING AND SV17033 ACTIVE | Q42: Thickener in Forward Mode | R42: 3 | T42: X | Z42: Unable to lower rake if thickener is not in FORWARD mode. | AA42: 2
O43: OP3 | P43: AUTO MODE: F17PO409 Running (Runtime > 5 seconds) | Q43: F19PO409 Startup Timer | R43: 0 | T43: X | Z43: Prevent energising solenoid valve if F17PO409 has been started and runtime < 5 seconds. Permissive to allow hydraulic oil pressure to build to operating point. | AA43: C
O44: CT1 | P44: ZAL17015 Active | R44: 0 | W44: X | X44: X | Z44: True in LOCAL AND AUTO Modes. Bypass for faulty switch. | AA44: 0
E45: SV17048 | F45: 2000-F17-PID-PR-10001 | G45: F17-HU-414 Flotation Tailings Thickener Rake Lift HPU Raise Rake Solenoid Valve | H45: F17HU414 Rake Raise | I45: Vendor | J45: Rexroth | L45: X | M45: AUTO MODE Active AND NI17030 >= P_Hi AND SV17033 Energised AND F17PO408 Running AND ZAH17014 Not Active AND F17PO409 Running (Runtime > 5 seconds) | N45: AUTO MODE Active AND (NI17030 < P_Hi OR ZAH17014 Active) | O45: OP1 | P45: SV17047 NOT ACTIVE | R45: 3 | T45: X | Z45: Control logic to be continually running when Thickener is in FORWARD MODE. Control logic to de-energise solenoid valve if during raising in AUTO MODE, ZAH17014 becomes active. | AA45: 2
M46: F17TH401_LCL Active AND HS17065A Active | N46: F17TH401_LCL Active AND HS17065A Released (Falling Edge) | O46: OP2 | P46: AUTO MODE: F17-PO-408 RUNNING AND SV17033 ACTIVE | Q46: Thickener in Forward Mode | R46: 3 | T46: X | X46: X | Z46: Unable to raise rake if thickener is not in FORWARD mode. Permissive does not apply in LOCAL. | AA46: 2
O47: OP3 | P47: AUTO MODE: F17PO409 Running (Runtime > 5 seconds) | Q47: F19PO409 Startup Timer | R47: 0 | T47: X | Z47: Prevent energising solenoid valve if F17PO409 has been started and runtime < 5 seconds. Permissive to allow hydraulic oil pressure to build to operating point. | AA47: C
O48: CT1 | P48: ZAH17014 Active | R48: 0 | W48: X | X48: X | Z48: True in LOCAL AND AUTO Modes. Bypass for faulty switch. | AA48: 0
E49: XV17091 | F49: 2000-F17-PID-PR-10002 | G49: F17-TH-401 Flotation Tailings Thickener Underflow Discharge Valve 1 - F17-PP-455 Suction | H49: F17PP455 Suction 1 | I49: Detail 4 | J49: FC | K49: X | L49: X | M49: F17-SEQ-0001 | N49: F17-SEQ-0002 | O49: OP1 | P49: XV17095 OPEN AND XV17102 CLOSED | Q49: Water Hammer Prevention | R49: 3 | T49: X | X49: X | Z49: To prevent water hammer on underflow pump start when Thickener Cone Valves are opened. Bypass for dumping of thickener. Suction Flush Valve must be Open and Suction Drain must be Closed. | AA49: 2
M50: Manually opened by Operator | N50: Manually closed by Operator
E51: XV17092 | F51: 2000-F17-PID-PR-10002 | G51: F17-TH-401 Flotation Tailings Thickener Underflow Discharge Valve 2 - F17-PP-456 Suction | H51: F17PP456 Suction 1 | I51: Detail 4 | J51: FC | K51: X | L51: X | M51: F17-SEQ-0001 | N51: F17-SEQ-0002 | O51: OP1 | P51: XV17096 OPEN AND XV17112 CLOSED | Q51: Water Hammer Prevention | R51: 3 | T51: X | X51: X | Z51: To prevent water hammer on underflow pump start when Thickener Cone Valves are opened. Bypass for dumping of thickener. Suction Flush Valve must be Open and Suction Drain must be Closed. | AA51: 2
M52: Manually opened by Operator | N52: Manually closed by Operator
E53: XV17093 | F53: 2000-F17-PID-PR-10002 | G53: F17-TH-401 Flotation Tailings Thickener Underflow Discharge Valve 3 - F17-PP-455 Suction | H53: F17PP455 Suction 2 | I53: Detail 4 | J53: FC | K53: X | L53: X | M53: F17-SEQ-0001 | N53: F17-SEQ-0002 | O53: OP1 | P53: XV17095 OPEN AND XV17102 CLOSED | Q53: Water Hammer Prevention | R53: 3 | T53: X | X53: X | Z53: To prevent water hammer on underflow pump start when Thickener Cone Valves are opened. Bypass for dumping of thickener. Suction Flush Valve must be Open and Suction Drain must be Closed. | AA53: 2
M54: Manually opened by Operator | N54: Manually closed by Operator
E55: XV17094 | F55: 2000-F17-PID-PR-10002 | G55: F17-TH-401 Flotation Tailings Thickener Underflow Discharge Valve 4 - F17-PP-456 Suction | H55: F17PP456 Suction 2 | I55: Detail 4 | J55: FC | K55: X | L55: X | M55: F17-SEQ-0001 | N55: F17-SEQ-0002 | O55: OP1 | P55: XV17096 OPEN AND XV17112 CLOSED | Q55: Water Hammer Prevention | R55: 3 | T55: X | X55: X | Z55: To prevent water hammer on underflow pump start when Thickener Cone Valves are opened. Bypass for dumping of thickener. Suction Flush Valve must be Open and Suction Drain must be Closed. | AA55: 2
...

Sheet 7. Control Valves
E1: KCGM GROWTH PROJECT
E2: PROCESS CONTROL TABLES - FLOTATION (F16, F17, F18)
E3: 2000-F16-LST-PR-10001
E4: CONTROL VALVES
O5: Permissive and Trips
A6: Area | B6: Type | C6: Loop No. | D6: Suffix | E6: Tag Name | F6: P&ID | G6: Valve Description | H6: Abbreviated Description (Faceplate) | I6: Valve Type | J6: Fail Position | K6: Manual | L6: Auto | M6: Open Condition (Auto Mode) | N6: Close Condition (Auto Mode) | O6: # | P6: Condition | Q6: Description (Faceplate) | R6: Delay On | S6: Delay Off | T6: Open Permissive | U6: Close Permissive | V6: Open Interlock | W6: Close Interlock | X6: Bypass | Y6: Reset Required | Z6: Comments | AA6: Rev
E7: FCV16011 | F7: 2000-F16-PID-PR-10001 | G7: F16-CF-411 Rougher Flotation Cell 1 Low Pressure Air Flow Control Valve | H7: F16CF11 Blower Air | I7: Vendor | J7: FL | K7: X | L7: X | M7: FIC16011 | N7: FIC16011 | AA7: B
E8: FCV16051 | F8: 2000-F16-PID-PR-10002 | G8: F16-CF-412 Rougher Flotation Cell 2 Low Pressure Air Flow Control Valve | H8: F16CF412 Blower Air | I8: Vendor | J8: FL | K8: X | L8: X | M8: FIC16051 | N8: FIC16051 | AA8: B
E9: LCV16013A | F9: 2000-F16-PID-PR-10002 | G9: F16-CF-412 Rougher Flotation Cell 2 Level Control Valve A | H9: F16CF412 Dart Valve A | I9: Vendor | J9: FL | K9: X | L9: X | M9: LIC16013A | N9: LIC16013A | Z9: Vendor specified operating range: 50 - 80% stroke. To be primary valve adjusting level when in Auto. To be confirmed during commissioning. Source: 2000-ME001.4-M02-50001. | AA9: 0
E10: LCV16013B | F10: 2000-F16-PID-PR-10002 | G10: F16-CF-412 Rougher Flotation Cell 2 Level Control Valve B | H10: F16CF412 Dart Valve B | I10: Vendor | J10: FL | K10: X | L10: X | M10: LIC16013B | N10: LIC16013B | Z10: Vendor specified operating range: 50 - 80% stroke. To be held at constant setpoint when in Auto. To be confirmed during commissioning. Source: 2000-ME001.4-M02-50001. | AA10: 0
E11: FCV16061 | F11: 2000-F16-PID-PR-10002 | G11: F16-CF-413 Rougher Flotation Cell 3 Low Pressure Air Flow Control Valve | H11: F16CF413 Blower Air | I11: Vendor | J11: FL | K11: X | L11: X | M11: FIC16061 | N11: FIC16061 | Z11: Source: 2000-ME001.4-M02-50001. | AA11: 0
E12: LCV16053A | F12: 2000-F16-PID-PR-10002 | G12: F16-CF-413 Rougher Flotation Cell 3 Level Control Valve A | H12: F16CF413 Dart Valve A | I12: Vendor | J12: FL | K12: X | L12: X | M12: LIC16053A | N12: LIC16053A | Z12: Vendor specified operating range: 50 - 80% stroke. To be primary valve adjusting level when in Auto. To be confirmed during commissioning. Source: 2000-ME001.4-M02-50001. | AA12: 0
E13: LCV16053B | F13: 2000-F16-PID-PR-10002 | G13: F16-CF-413 Rougher Flotation Cell 3 Level Control Valve B | H13: F16CF413 Dart Valve B | I13: Vendor | J13: FL | K13: X | L13: X | M13: LIC16053B | N13: LIC16053B | Z13: Vendor specified operating range: 50 - 80% stroke. To be held at constant setpoint when in Auto. To be confirmed during commissioning. Source: 2000-ME001.4-M02-50001. | AA13: 0
E14: FCV16081 | F14: 2000-F16-PID-PR-10003 | G14: F16-CF-414 Scavenger Flotation Cell 1 Low Pressure Air Flow Control Valve | H14: F16CF414 Blower Air | I14: Vendor | J14: FL | K14: X | L14: X | M14: FIC16081 | N14: FIC16081 | Z14: Source: 2000-ME001.4-M02-50001. | AA14: 0
E15: LCV16063A | F15: 2000-F16-PID-PR-10003 | G15: F16-CF-414 Scavenger Flotation Cell 1 Level Control Valve A | H15: F16CF414 Dart Valve A | I15: Vendor | J15: FL | K15: X | L15: X | M15: LIC16063A | N15: LIC16063A | Z15: Vendor specified operating range: 50 - 80% stroke. To be primary valve adjusting level when in Auto. To be confirmed during commissioning. Source: 2000-ME001.4-M02-50001. | AA15: 0
E16: LCV16063B | F16: 2000-F16-PID-PR-10003 | G16: F16-CF-414 Scavenger Flotation Cell 1 Level Control Valve B | H16: F16CF414 Dart Valve B | I16: Vendor | J16: FL | K16: X | L16: X | M16: LIC16063B | N16: LIC16063B | Z16: Vendor specified operating range: 50 - 80% stroke. To be held at constant setpoint when in Auto. To be confirmed during commissioning. Source: 2000-ME001.4-M02-50001. | AA16: 0
E17: FCV16091 | F17: 2000-F16-PID-PR-10003 | G17: F16-CF-415 Scavenger Flotation Cell 2 Low Pressure Air Flow Control Valve | H17: F16CF415 Blower Air | I17: Vendor | J17: FL | K17: X | L17: X | M17: FIC16091 | N17: FIC16091 | Z17: Source: 2000-ME001.4-M02-50001. | AA17: 0
E18: LCV16083A | F18: 2000-F16-PID-PR-10003 | G18: F16-CF-415 Scavenger Flotation Cell 2 Level Control Valve A | H18: F16CF415 Dart Valve A | I18: Vendor | J18: FL | K18: X | L18: X | M18: LIC16083A | N18: LIC16083A | Z18: Vendor specified operating range: 50 - 80% stroke. To be primary valve adjusting level when in Auto. To be confirmed during commissioning. Source: 2000-ME001.4-M02-50001. | AA18: 0
E19: LCV16083B | F19: 2000-F16-PID-PR-10003 | G19: F16-CF-415 Scavenger Flotation Cell 2 Level Control Valve B | H19: F16CF415 Dart Valve B | I19: Vendor | J19: FL | K19: X | L19: X | M19: LIC16083B | N19: LIC16083B | Z19: Vendor specified operating range: 50 - 80% stroke. To be held at constant setpoint when in Auto. To be confirmed during commissioning. Source: 2000-ME001.4-M02-50001. | AA19: 0
